[ 2024-04-05 14:32:13,594 ] 96 werkzeug - INFO - [31m[1mWARNING: This is a development server. Do not use it in a production deployment. Use a production WSGI server instead.[0m
 * Running on http://127.0.0.1:5000
[ 2024-04-05 14:32:13,595 ] 96 werkzeug - INFO - [33mPress CTRL+C to quit[0m
[ 2024-04-05 14:32:19,237 ] 96 werkzeug - INFO - 127.0.0.1 - - [05/Apr/2024 14:32:19] "GET / HTTP/1.1" 200 -
[ 2024-04-05 14:32:19,404 ] 96 werkzeug - INFO - 127.0.0.1 - - [05/Apr/2024 14:32:19] "[36mGET /static/css/index.css HTTP/1.1[0m" 304 -
[ 2024-04-05 14:32:19,414 ] 96 werkzeug - INFO - 127.0.0.1 - - [05/Apr/2024 14:32:19] "[36mGET /static/css/corn%20diplay.png HTTP/1.1[0m" 304 -
[ 2024-04-05 14:32:19,447 ] 96 werkzeug - INFO - 127.0.0.1 - - [05/Apr/2024 14:32:19] "[35m[1mGET /static/css/corn%20video.mp4 HTTP/1.1[0m" 206 -
[ 2024-04-05 14:32:42,333 ] 828 app - ERROR - Exception on /openwebcam [POST]
Traceback (most recent call last):
  File "C:\Users\MAYUR\anaconda3\envs\SeedGermination\Lib\site-packages\urllib3\connection.py", line 198, in _new_conn
    sock = connection.create_connection(
           ^^^^^^^^^^^^^^^^^^^^^^^^^^^^^
  File "C:\Users\MAYUR\anaconda3\envs\SeedGermination\Lib\site-packages\urllib3\util\connection.py", line 85, in create_connection
    raise err
  File "C:\Users\MAYUR\anaconda3\envs\SeedGermination\Lib\site-packages\urllib3\util\connection.py", line 73, in create_connection
    sock.connect(sa)
TimeoutError: [WinError 10060] A connection attempt failed because the connected party did not properly respond after a period of time, or established connection failed because connected host has failed to respond

The above exception was the direct cause of the following exception:

Traceback (most recent call last):
  File "C:\Users\MAYUR\anaconda3\envs\SeedGermination\Lib\site-packages\urllib3\connectionpool.py", line 793, in urlopen
    response = self._make_request(
               ^^^^^^^^^^^^^^^^^^^
  File "C:\Users\MAYUR\anaconda3\envs\SeedGermination\Lib\site-packages\urllib3\connectionpool.py", line 496, in _make_request
    conn.request(
  File "C:\Users\MAYUR\anaconda3\envs\SeedGermination\Lib\site-packages\urllib3\connection.py", line 400, in request
    self.endheaders()
  File "C:\Users\MAYUR\anaconda3\envs\SeedGermination\Lib\http\client.py", line 1289, in endheaders
    self._send_output(message_body, encode_chunked=encode_chunked)
  File "C:\Users\MAYUR\anaconda3\envs\SeedGermination\Lib\http\client.py", line 1048, in _send_output
    self.send(msg)
  File "C:\Users\MAYUR\anaconda3\envs\SeedGermination\Lib\http\client.py", line 986, in send
    self.connect()
  File "C:\Users\MAYUR\anaconda3\envs\SeedGermination\Lib\site-packages\urllib3\connection.py", line 238, in connect
    self.sock = self._new_conn()
                ^^^^^^^^^^^^^^^^
  File "C:\Users\MAYUR\anaconda3\envs\SeedGermination\Lib\site-packages\urllib3\connection.py", line 207, in _new_conn
    raise ConnectTimeoutError(
urllib3.exceptions.ConnectTimeoutError: (<urllib3.connection.HTTPConnection object at 0x0000022517C3AE10>, 'Connection to 192.0.0.4 timed out. (connect timeout=None)')

The above exception was the direct cause of the following exception:

Traceback (most recent call last):
  File "C:\Users\MAYUR\anaconda3\envs\SeedGermination\Lib\site-packages\requests\adapters.py", line 486, in send
    resp = conn.urlopen(
           ^^^^^^^^^^^^^
  File "C:\Users\MAYUR\anaconda3\envs\SeedGermination\Lib\site-packages\urllib3\connectionpool.py", line 847, in urlopen
    retries = retries.increment(
              ^^^^^^^^^^^^^^^^^^
  File "C:\Users\MAYUR\anaconda3\envs\SeedGermination\Lib\site-packages\urllib3\util\retry.py", line 515, in increment
    raise MaxRetryError(_pool, url, reason) from reason  # type: ignore[arg-type]
    ^^^^^^^^^^^^^^^^^^^^^^^^^^^^^^^^^^^^^^^^^^^^^^^^^^^
urllib3.exceptions.MaxRetryError: HTTPConnectionPool(host='192.0.0.4', port=8080): Max retries exceeded with url: /shot.jpg (Caused by ConnectTimeoutError(<urllib3.connection.HTTPConnection object at 0x0000022517C3AE10>, 'Connection to 192.0.0.4 timed out. (connect timeout=None)'))

During handling of the above exception, another exception occurred:

Traceback (most recent call last):
  File "C:\Users\MAYUR\anaconda3\envs\SeedGermination\Lib\site-packages\flask\app.py", line 1463, in wsgi_app
    response = self.full_dispatch_request()
               ^^^^^^^^^^^^^^^^^^^^^^^^^^^^
  File "C:\Users\MAYUR\anaconda3\envs\SeedGermination\Lib\site-packages\flask\app.py", line 872, in full_dispatch_request
    rv = self.handle_user_exception(e)
         ^^^^^^^^^^^^^^^^^^^^^^^^^^^^^
  File "C:\Users\MAYUR\anaconda3\envs\SeedGermination\Lib\site-packages\flask\app.py", line 870, in full_dispatch_request
    rv = self.dispatch_request()
         ^^^^^^^^^^^^^^^^^^^^^^^
  File "C:\Users\MAYUR\anaconda3\envs\SeedGermination\Lib\site-packages\flask\app.py", line 855, in dispatch_request
    return self.ensure_sync(self.view_functions[rule.endpoint])(**view_args)  # type: ignore[no-any-return]
           ^^^^^^^^^^^^^^^^^^^^^^^^^^^^^^^^^^^^^^^^^^^^^^^^^^^^^^^^^^^^^^^^^
  File "d:\Computer_science\BE_PROJECT\Seed_Project\app.py", line 50, in predict_datapoint
    img_resp = requests.get(url)
               ^^^^^^^^^^^^^^^^^
  File "C:\Users\MAYUR\anaconda3\envs\SeedGermination\Lib\site-packages\requests\api.py", line 73, in get
    return request("get", url, params=params, **kwargs)
           ^^^^^^^^^^^^^^^^^^^^^^^^^^^^^^^^^^^^^^^^^^^^
  File "C:\Users\MAYUR\anaconda3\envs\SeedGermination\Lib\site-packages\requests\api.py", line 59, in request
    return session.request(method=method, url=url, **kwargs)
           ^^^^^^^^^^^^^^^^^^^^^^^^^^^^^^^^^^^^^^^^^^^^^^^^^
  File "C:\Users\MAYUR\anaconda3\envs\SeedGermination\Lib\site-packages\requests\sessions.py", line 589, in request
    resp = self.send(prep, **send_kwargs)
           ^^^^^^^^^^^^^^^^^^^^^^^^^^^^^^
  File "C:\Users\MAYUR\anaconda3\envs\SeedGermination\Lib\site-packages\requests\sessions.py", line 703, in send
    r = adapter.send(request, **kwargs)
        ^^^^^^^^^^^^^^^^^^^^^^^^^^^^^^^
  File "C:\Users\MAYUR\anaconda3\envs\SeedGermination\Lib\site-packages\requests\adapters.py", line 507, in send
    raise ConnectTimeout(e, request=request)
requests.exceptions.ConnectTimeout: HTTPConnectionPool(host='192.0.0.4', port=8080): Max retries exceeded with url: /shot.jpg (Caused by ConnectTimeoutError(<urllib3.connection.HTTPConnection object at 0x0000022517C3AE10>, 'Connection to 192.0.0.4 timed out. (connect timeout=None)'))
[ 2024-04-05 14:32:42,346 ] 96 werkzeug - INFO - 127.0.0.1 - - [05/Apr/2024 14:32:42] "[35m[1mPOST /openwebcam HTTP/1.1[0m" 500 -
