[ 2024-04-03 12:57:56,232 ] 96 werkzeug - INFO - [31m[1mWARNING: This is a development server. Do not use it in a production deployment. Use a production WSGI server instead.[0m
 * Running on http://127.0.0.1:5000
[ 2024-04-03 12:57:56,232 ] 96 werkzeug - INFO - [33mPress CTRL+C to quit[0m
[ 2024-04-03 12:58:11,539 ] 96 werkzeug - INFO - 127.0.0.1 - - [03/Apr/2024 12:58:11] "GET / HTTP/1.1" 200 -
[ 2024-04-03 12:58:11,629 ] 96 werkzeug - INFO - 127.0.0.1 - - [03/Apr/2024 12:58:11] "[36mGET /static/css/corn%20diplay.png HTTP/1.1[0m" 304 -
[ 2024-04-03 12:58:11,634 ] 96 werkzeug - INFO - 127.0.0.1 - - [03/Apr/2024 12:58:11] "[36mGET /static/css/index.css HTTP/1.1[0m" 304 -
[ 2024-04-03 12:58:11,661 ] 96 werkzeug - INFO - 127.0.0.1 - - [03/Apr/2024 12:58:11] "[35m[1mGET /static/css/corn%20video.mp4 HTTP/1.1[0m" 206 -
[ 2024-04-03 12:58:11,666 ] 96 werkzeug - INFO - 127.0.0.1 - - [03/Apr/2024 12:58:11] "[35m[1mGET /static/css/corn%20video.mp4 HTTP/1.1[0m" 206 -
[ 2024-04-03 12:58:39,604 ] 96 werkzeug - INFO - 127.0.0.1 - - [03/Apr/2024 12:58:39] "POST /openwebcam HTTP/1.1" 200 -
[ 2024-04-03 12:58:39,618 ] 96 werkzeug - INFO - 127.0.0.1 - - [03/Apr/2024 12:58:39] "[36mGET /static/css/displayImage.css HTTP/1.1[0m" 304 -
[ 2024-04-03 12:58:39,619 ] 96 werkzeug - INFO - 127.0.0.1 - - [03/Apr/2024 12:58:39] "[36mGET /static/css/corn%202.jpg HTTP/1.1[0m" 304 -
[ 2024-04-03 12:58:45,892 ] 96 werkzeug - INFO - 127.0.0.1 - - [03/Apr/2024 12:58:45] "POST /RunningMacros HTTP/1.1" 200 -
[ 2024-04-03 12:58:45,903 ] 96 werkzeug - INFO - 127.0.0.1 - - [03/Apr/2024 12:58:45] "[36mGET /static/css/ViewResults.css HTTP/1.1[0m" 304 -
[ 2024-04-03 12:58:45,903 ] 96 werkzeug - INFO - 127.0.0.1 - - [03/Apr/2024 12:58:45] "[36mGET /static/css/corn%201.jpg HTTP/1.1[0m" 304 -
[ 2024-04-03 12:58:48,323 ] 21 root - INFO - New data : 
    Area     X     Y    XM    YM  Perimeter    BX    BY  Width  Height
0  118.0  61.0  83.0  61.0  83.0       95.0  57.0  72.0    9.0    27.0
[ 2024-04-03 12:58:48,961 ] 96 werkzeug - INFO - 127.0.0.1 - - [03/Apr/2024 12:58:48] "POST /showingResults HTTP/1.1" 200 -
[ 2024-04-03 12:58:48,973 ] 96 werkzeug - INFO - 127.0.0.1 - - [03/Apr/2024 12:58:48] "[36mGET /static/css/Results.css HTTP/1.1[0m" 304 -
[ 2024-04-03 12:58:48,982 ] 96 werkzeug - INFO - 127.0.0.1 - - [03/Apr/2024 12:58:48] "GET /static/seed_results_plot.png HTTP/1.1" 200 -
[ 2024-04-03 12:58:48,982 ] 96 werkzeug - INFO - 127.0.0.1 - - [03/Apr/2024 12:58:48] "GET /static/seed_results_pie_chart.png HTTP/1.1" 200 -
[ 2024-04-03 13:01:28,810 ] 96 werkzeug - INFO - 127.0.0.1 - - [03/Apr/2024 13:01:28] "GET / HTTP/1.1" 200 -
[ 2024-04-03 13:01:28,820 ] 96 werkzeug - INFO - 127.0.0.1 - - [03/Apr/2024 13:01:28] "[36mGET /static/css/index.css HTTP/1.1[0m" 304 -
[ 2024-04-03 13:01:28,820 ] 96 werkzeug - INFO - 127.0.0.1 - - [03/Apr/2024 13:01:28] "[36mGET /static/css/corn%20diplay.png HTTP/1.1[0m" 304 -
[ 2024-04-03 13:01:28,859 ] 96 werkzeug - INFO - 127.0.0.1 - - [03/Apr/2024 13:01:28] "[35m[1mGET /static/css/corn%20video.mp4 HTTP/1.1[0m" 206 -
[ 2024-04-03 13:01:33,555 ] 828 app - ERROR - Exception on /openwebcam [POST]
Traceback (most recent call last):
  File "C:\Users\MAYUR\anaconda3\envs\SeedGermination\Lib\site-packages\urllib3\connection.py", line 198, in _new_conn
    sock = connection.create_connection(
           ^^^^^^^^^^^^^^^^^^^^^^^^^^^^^
  File "C:\Users\MAYUR\anaconda3\envs\SeedGermination\Lib\site-packages\urllib3\util\connection.py", line 85, in create_connection
    raise err
  File "C:\Users\MAYUR\anaconda3\envs\SeedGermination\Lib\site-packages\urllib3\util\connection.py", line 73, in create_connection
    sock.connect(sa)
ConnectionRefusedError: [WinError 10061] No connection could be made because the target machine actively refused it

The above exception was the direct cause of the following exception:

Traceback (most recent call last):
  File "C:\Users\MAYUR\anaconda3\envs\SeedGermination\Lib\site-packages\urllib3\connectionpool.py", line 793, in urlopen
    response = self._make_request(
               ^^^^^^^^^^^^^^^^^^^
  File "C:\Users\MAYUR\anaconda3\envs\SeedGermination\Lib\site-packages\urllib3\connectionpool.py", line 496, in _make_request
    conn.request(
  File "C:\Users\MAYUR\anaconda3\envs\SeedGermination\Lib\site-packages\urllib3\connection.py", line 400, in request
    self.endheaders()
  File "C:\Users\MAYUR\anaconda3\envs\SeedGermination\Lib\http\client.py", line 1289, in endheaders
    self._send_output(message_body, encode_chunked=encode_chunked)
  File "C:\Users\MAYUR\anaconda3\envs\SeedGermination\Lib\http\client.py", line 1048, in _send_output
    self.send(msg)
  File "C:\Users\MAYUR\anaconda3\envs\SeedGermination\Lib\http\client.py", line 986, in send
    self.connect()
  File "C:\Users\MAYUR\anaconda3\envs\SeedGermination\Lib\site-packages\urllib3\connection.py", line 238, in connect
    self.sock = self._new_conn()
                ^^^^^^^^^^^^^^^^
  File "C:\Users\MAYUR\anaconda3\envs\SeedGermination\Lib\site-packages\urllib3\connection.py", line 213, in _new_conn
    raise NewConnectionError(
urllib3.exceptions.NewConnectionError: <urllib3.connection.HTTPConnection object at 0x00000219B0270B90>: Failed to establish a new connection: [WinError 10061] No connection could be made because the target machine actively refused it

The above exception was the direct cause of the following exception:

Traceback (most recent call last):
  File "C:\Users\MAYUR\anaconda3\envs\SeedGermination\Lib\site-packages\requests\adapters.py", line 486, in send
    resp = conn.urlopen(
           ^^^^^^^^^^^^^
  File "C:\Users\MAYUR\anaconda3\envs\SeedGermination\Lib\site-packages\urllib3\connectionpool.py", line 847, in urlopen
    retries = retries.increment(
              ^^^^^^^^^^^^^^^^^^
  File "C:\Users\MAYUR\anaconda3\envs\SeedGermination\Lib\site-packages\urllib3\util\retry.py", line 515, in increment
    raise MaxRetryError(_pool, url, reason) from reason  # type: ignore[arg-type]
    ^^^^^^^^^^^^^^^^^^^^^^^^^^^^^^^^^^^^^^^^^^^^^^^^^^^
urllib3.exceptions.MaxRetryError: HTTPConnectionPool(host='172.20.10.7', port=8080): Max retries exceeded with url: /shot.jpg (Caused by NewConnectionError('<urllib3.connection.HTTPConnection object at 0x00000219B0270B90>: Failed to establish a new connection: [WinError 10061] No connection could be made because the target machine actively refused it'))

During handling of the above exception, another exception occurred:

Traceback (most recent call last):
  File "C:\Users\MAYUR\anaconda3\envs\SeedGermination\Lib\site-packages\flask\app.py", line 1463, in wsgi_app
    response = self.full_dispatch_request()
               ^^^^^^^^^^^^^^^^^^^^^^^^^^^^
  File "C:\Users\MAYUR\anaconda3\envs\SeedGermination\Lib\site-packages\flask\app.py", line 872, in full_dispatch_request
    rv = self.handle_user_exception(e)
         ^^^^^^^^^^^^^^^^^^^^^^^^^^^^^
  File "C:\Users\MAYUR\anaconda3\envs\SeedGermination\Lib\site-packages\flask\app.py", line 870, in full_dispatch_request
    rv = self.dispatch_request()
         ^^^^^^^^^^^^^^^^^^^^^^^
  File "C:\Users\MAYUR\anaconda3\envs\SeedGermination\Lib\site-packages\flask\app.py", line 855, in dispatch_request
    return self.ensure_sync(self.view_functions[rule.endpoint])(**view_args)  # type: ignore[no-any-return]
           ^^^^^^^^^^^^^^^^^^^^^^^^^^^^^^^^^^^^^^^^^^^^^^^^^^^^^^^^^^^^^^^^^
  File "d:\Computer_science\BE_PROJECT\Seed_Project\app.py", line 50, in predict_datapoint
    img_resp = requests.get(url)
               ^^^^^^^^^^^^^^^^^
  File "C:\Users\MAYUR\anaconda3\envs\SeedGermination\Lib\site-packages\requests\api.py", line 73, in get
    return request("get", url, params=params, **kwargs)
           ^^^^^^^^^^^^^^^^^^^^^^^^^^^^^^^^^^^^^^^^^^^^
  File "C:\Users\MAYUR\anaconda3\envs\SeedGermination\Lib\site-packages\requests\api.py", line 59, in request
    return session.request(method=method, url=url, **kwargs)
           ^^^^^^^^^^^^^^^^^^^^^^^^^^^^^^^^^^^^^^^^^^^^^^^^^
  File "C:\Users\MAYUR\anaconda3\envs\SeedGermination\Lib\site-packages\requests\sessions.py", line 589, in request
    resp = self.send(prep, **send_kwargs)
           ^^^^^^^^^^^^^^^^^^^^^^^^^^^^^^
  File "C:\Users\MAYUR\anaconda3\envs\SeedGermination\Lib\site-packages\requests\sessions.py", line 703, in send
    r = adapter.send(request, **kwargs)
        ^^^^^^^^^^^^^^^^^^^^^^^^^^^^^^^
  File "C:\Users\MAYUR\anaconda3\envs\SeedGermination\Lib\site-packages\requests\adapters.py", line 519, in send
    raise ConnectionError(e, request=request)
requests.exceptions.ConnectionError: HTTPConnectionPool(host='172.20.10.7', port=8080): Max retries exceeded with url: /shot.jpg (Caused by NewConnectionError('<urllib3.connection.HTTPConnection object at 0x00000219B0270B90>: Failed to establish a new connection: [WinError 10061] No connection could be made because the target machine actively refused it'))
[ 2024-04-03 13:01:33,569 ] 96 werkzeug - INFO - 127.0.0.1 - - [03/Apr/2024 13:01:33] "[35m[1mPOST /openwebcam HTTP/1.1[0m" 500 -
[ 2024-04-03 13:01:51,453 ] 96 werkzeug - INFO - 127.0.0.1 - - [03/Apr/2024 13:01:51] "GET / HTTP/1.1" 200 -
[ 2024-04-03 13:01:51,471 ] 96 werkzeug - INFO - 127.0.0.1 - - [03/Apr/2024 13:01:51] "[36mGET /static/css/index.css HTTP/1.1[0m" 304 -
[ 2024-04-03 13:01:51,472 ] 96 werkzeug - INFO - 127.0.0.1 - - [03/Apr/2024 13:01:51] "[36mGET /static/css/corn%20diplay.png HTTP/1.1[0m" 304 -
[ 2024-04-03 13:01:51,507 ] 96 werkzeug - INFO - 127.0.0.1 - - [03/Apr/2024 13:01:51] "[35m[1mGET /static/css/corn%20video.mp4 HTTP/1.1[0m" 206 -
[ 2024-04-03 13:01:51,513 ] 96 werkzeug - INFO - 127.0.0.1 - - [03/Apr/2024 13:01:51] "[35m[1mGET /static/css/corn%20video.mp4 HTTP/1.1[0m" 206 -
[ 2024-04-03 13:02:39,910 ] 96 werkzeug - INFO - 127.0.0.1 - - [03/Apr/2024 13:02:39] "POST /openwebcam HTTP/1.1" 200 -
[ 2024-04-03 13:03:17,991 ] 96 werkzeug - INFO - 127.0.0.1 - - [03/Apr/2024 13:03:17] "POST /openwebcam HTTP/1.1" 200 -
[ 2024-04-03 13:03:19,340 ] 828 app - ERROR - Exception on /openwebcam [POST]
Traceback (most recent call last):
  File "C:\Users\MAYUR\anaconda3\envs\SeedGermination\Lib\site-packages\flask\app.py", line 1463, in wsgi_app
    response = self.full_dispatch_request()
               ^^^^^^^^^^^^^^^^^^^^^^^^^^^^
  File "C:\Users\MAYUR\anaconda3\envs\SeedGermination\Lib\site-packages\flask\app.py", line 872, in full_dispatch_request
    rv = self.handle_user_exception(e)
         ^^^^^^^^^^^^^^^^^^^^^^^^^^^^^
  File "C:\Users\MAYUR\anaconda3\envs\SeedGermination\Lib\site-packages\flask\app.py", line 870, in full_dispatch_request
    rv = self.dispatch_request()
         ^^^^^^^^^^^^^^^^^^^^^^^
  File "C:\Users\MAYUR\anaconda3\envs\SeedGermination\Lib\site-packages\flask\app.py", line 855, in dispatch_request
    return self.ensure_sync(self.view_functions[rule.endpoint])(**view_args)  # type: ignore[no-any-return]
           ^^^^^^^^^^^^^^^^^^^^^^^^^^^^^^^^^^^^^^^^^^^^^^^^^^^^^^^^^^^^^^^^^
  File "d:\Computer_science\BE_PROJECT\Seed_Project\app.py", line 102, in predict_datapoint
    return render_template('displayImage.html',captured_image=captured_image)
                           ^^^^^^^^^^^^^^^^^^^
UnboundLocalError: cannot access local variable 'captured_image' where it is not associated with a value
[ 2024-04-03 13:03:19,341 ] 96 werkzeug - INFO - 127.0.0.1 - - [03/Apr/2024 13:03:19] "[35m[1mPOST /openwebcam HTTP/1.1[0m" 500 -
